<?xml version="1.0"?>
<robot xmlns:xacro="http://ros.org/wiki/xacro">

<xacro:macro name="prarob_manipulator" params="parent *origin">
  <joint name="origin_to_link1" type="fixed">
    <xacro:insert_block name="origin" />
    <parent link="${parent}" />
    <child link="base" />
    <origin xyz="0.0 0.0 0.0" rpy="0 0 0"/>
    <axis xyz="0 0 1" />
  </joint>

  <!-- Link 1 - primitives-->
  <!--link name="link1">
    <visual>
      <origin xyz="0 0 0.5" rpy="0 0 0"/>
      <geometry>
        <box size="0.05 0.05 1.0"/>
      </geometry>
      <color rgba="0 0 0.8 1"/>
    </visual>

    <collision>
      <origin xyz="0 0 0" rpy="0 0 0"/>
      <geometry>
        <box size="0.05 0.05 1.0"/>
      </geometry>
    </collision>
  </link-->

<!-- Link 1 - base -->
  <link name="base">
    <visual>
      <origin rpy="1.57075 0 0" xyz="0 0 0"/>
      <geometry>
        <mesh filename="package://connect_the_bdots/meshes/SeminarBase.stl" scale="0.001 0.001 0.001"/>
      </geometry>
      <material name="">
        <color rgba="0.054901960784313725 0.054901960784313725 0.06274509803921569 1.0"/>
      </material>
    </visual>
    <collision>
      <origin rpy="1.57075 0 0" xyz="0 0 0"/>
      <geometry>
        <mesh filename="package://connect_the_bdots/meshes/SeminarBase.stl" scale="0.001 0.001 0.001"/>
      </geometry>
    </collision>

  </link>

  <!-- Joint base -->
  <joint name="base_to_link_90" type="revolute">
    <parent link="base"/>
    <child link="link_90"/>
    <origin xyz="0.0 0.0 0.04" rpy="0 0 0"/>
    <axis xyz="0 0 1"/>
    <limit velocity="10.0" effort="1" lower="0" upper="2.82743338823" />
  </joint>



  <!-- Link 2 - link 90-->
  <link name="link_90">
     <visual>
      <origin rpy="1.57075 0 0" xyz="0 0 0"/>
      <geometry>
        <mesh filename="package://connect_the_bdots/meshes/SeminarLink90.stl" scale="0.001 0.001 0.001"/>
      </geometry>
      <material name="">
        <color rgba="0.054901960784313725 0.054901960784313725 0.06274509803921569 1.0"/>
      </material>
    </visual>
    <collision>
      <origin rpy="1.57075 0 0" xyz="0 0 0"/>
      <geometry>
        <mesh filename="package://connect_the_bdots/meshes/SeminarLink90.stl" scale="0.001 0.001 0.001"/>
      </geometry>
    </collision>
  </link>

 <!-- Joint base -> xl -->
  <joint name="link_90_to_xl" type="fixed">
    <parent link="link_90"/>
    <child link="motor1"/>
    <origin xyz="0.0 0.0 0.030" rpy="0 0 0"/>
    <axis xyz="0 0 1"/>
    <limit velocity="10.0" effort="1" lower="-2.82743338823" upper="2.82743338823" />
  </joint>

  <!-- Motor 1-->
  <link name="motor1">
     <visual>
      <origin rpy="1.57075 0 0" xyz="0 0 0.01"/>
      <geometry>
        <mesh filename="package://connect_the_bdots/meshes/SeminarXL-430_new.stl" scale="0.001 0.001 0.001"/>
      </geometry>
      <material name="">
        <color rgba="0.054901960784313725 0.054901960784313725 0.06274509803921569 1.0"/>
      </material>
    </visual>
    <collision>
      <origin rpy="1.57075 0 0" xyz="0 0 0.01"/>
      <geometry>
        <mesh filename="package://connect_the_bdots/meshes/SeminarXL-430_new.stl" scale="0.001 0.001 0.001"/>
      </geometry>
    </collision>
  </link>


  <!-- Joint -->
  <joint name="xl_to_link_RR" type="revolute">
    <parent link="motor1"/>
    <child link="link_RR"/>
    <origin xyz="0.0 0.001 0.005" rpy="0 0 0"/>
    <axis xyz="0 1 0"/>
    <limit velocity="10.0" effort="1" lower="-2.82743338823" upper="2.82743338823" />
  </joint>

  <!-- Link 3 - link RR-->
  <link name="link_RR">
       <visual>
      <origin rpy="1.57075 0 1.57075" xyz="0.0 0.017 0.005 "/>
      <geometry>
        <mesh filename="package://connect_the_bdots/meshes/SeminarLinkRR.stl" scale="0.001 0.001 0.001"/>
      </geometry>
      <material name="">
        <color rgba="0.054901960784313725 0.054901960784313725 0.06274509803921569 1.0"/>
      </material>
    </visual>
    <collision>
      <origin rpy="1.57075 0 0" xyz="0.0 0.017 0.005"/>
      <geometry>
        <mesh filename="package://connect_the_bdots/meshes/SeminarLinkRR.stl" scale="0.001 0.001 0.001"/>
      </geometry>
    </collision>
  </link>

   <!-- Joint -->
  <joint name="link_RR_to_xl" type="revolute">
    <parent link="link_RR"/>
    <child link="motor2"/>
    <origin xyz="-0.18 0.0 0.0" rpy="0 0 0"/>
    <axis xyz="1 0 0"/>
    <limit velocity="10.0" effort="1" lower="-2.82743338823" upper="2.82743338823" />
  </joint>

    <!-- Motor 2-->
  <link name="motor2">
     <visual>
      <origin rpy="1.57075 0 0" xyz="0 0 0.0"/>
      <geometry>
        <mesh filename="package://connect_the_bdots/meshes/SeminarXL-430_new.stl" scale="0.001 0.001 0.001"/>
      </geometry>
      <material name="">
        <color rgba="0.054901960784313725 0.054901960784313725 0.06274509803921569 1.0"/>
      </material>
    </visual>
    <collision>
      <origin rpy="1.57075 0 1.57075" xyz="0 0 0.01"/>
      <geometry>
        <mesh filename="package://connect_the_bdots/meshes/SeminarXL-430_new.stl" scale="0.001 0.001 0.001"/>
      </geometry>
    </collision>
  </link>

    <!-- Joint 5 -->
  <!-- <joint name="xl_to_" type="fixed">
    <parent link="link2"/>
    <child link="link3"/>
    <origin xyz="0.0 0.0 0.02" rpy="0 0 0"/>
    <axis xyz="1 0 0"/>
    <limit velocity="10.0" effort="1" lower="-2.82743338823" upper="2.82743338823" />
  </joint> -->


  <!-- Link 4 - link marker-->
  <!-- <link name="link3">
       <visual>
      <origin rpy="1.57075 0 0" xyz="0.02 0 0.03"/>
      <geometry>
        <mesh filename="package://connect_the_bdots/meshes/SeminarLinkMarker.stl" scale="0.001 0.001 0.001"/>
      </geometry>
      <material name="">
        <color rgba="0.054901960784313725 0.054901960784313725 0.06274509803921569 1.0"/>
      </material>
    </visual>
    <collision>
      <origin rpy="1.57075 0 0" xyz="0.02 0 0.03"/>
      <geometry>
        <mesh filename="package://connect_the_bdots/meshes/SeminarLinkMarker.stl" scale="0.001 0.001 0.001"/>
      </geometry>
    </collision>
  </link> -->



  <!-- Joint 3 -->
  <!-- <joint name="joint3" type="revolute">
    <parent link="link3"/>
    <child link="link_tool"/>
    <origin xyz="0.0 0.0 1.0" rpy="0 0 0"/>
    <axis xyz="1 0 0"/>
    <limit velocity="10.0" effort="1" lower="-2.82743338823" upper="2.82743338823" />
  </joint> -->

  <!-- link_tool -->
  <!-- <link name="link_tool">
     <visual>
      <origin rpy="1.57075 0 0" xyz="0 0 1"/>
      <geometry>
        <mesh filename="package://connect_the_bdots/meshes/SeminarLinkMarker.stl" scale="0.001 0.001 0.001"/>
      </geometry>
      <material name="">
        <color rgba="0.054901960784313725 0.054901960784313725 0.06274509803921569 1.0"/>
      </material>
    </visual>
    <collision>
      <origin rpy="1.57075 0 0" xyz="0 0 0"/>
      <geometry>
        <mesh filename="package://connect_the_bdots/meshes/SeminarLinkMarker.stl" scale="0.001 0.001 0.001"/>
      </geometry>
    </collision>
  </link> -->


</xacro:macro>
</robot>
